Workbook

Sheet Plantilla Principal
A1: Columna 1 | B1: Total pedido S/iva | C1: Uso | D1: C/IVA | E1: Desc | F1: Incidencia
A2: Perfiles | B2: ='Plantilla Pedido'!L2-'Plantilla Retazo'!K4-'Plantilla Retazo'!W4 | C2: 1 | D2: =B2*1.21*C2 | E2: =B2*1.105*C2 | F2: =IF(B2="","",E2/$E$11) | H2: Perfiles | K2: Vidrios
A3: Accesorios resto | C3: 1 | D3: =B3*1.21 | E3: =B3*1.105 | F3: =IF(B3="","",E3/$E$11) | H3: Kg consumidos | I3: 1 | K3: m2 utilizados | L3: =SUM(B6:B7)*1.105
A4: Bipuntos | B4: 0 | C4: 1 | D4: =B4*1.21 | E4: =B4*1.105 | F4: =IF(B4="","",E4/$E$11) | H4: Kg comprados | I4: 1 | K4: % perdidas estimado | L4: 0.2
A5: Desperdicio perfiles | C5: 1 | D5: =B5*1.21*C5 | E5: =B5*1.105*C5 | F5: =IF(B5="","",E5/$E$11) | H5: Factor de seguridad | I5: 0 | K5: Costo real est | L5: =L3*(1+L4)
A6: Vidrios LAMIN | C6: 1 | D6: =B6*1.21 | E6: =B6*1.105 | F6: =IF(B6="","",E6/$E$11) | H6: CF | K6: Beneficio real est | L6: =F16+F17-L5
A7: Vidrios Crudos | B7: 0 | C7: 1 | D7: =B7*1.21 | E7: =B7*1.105 | F7: =IF(B7="","",E7/$E$11) | H7: $/dia MO | I7: 461529
A8: Vidrios Vidrial DVH | C8: 1 | D8: =B8*1.21 | E8: =B8*1.105 | F8: =IF(B8="","",E8/$E$11) | H8: Dias previstos | I8: 0
A9: Vidrios Vidrial Templados | C9: 1 | D9: =B9*1.21 | E9: =B9*1.105 | F9: =IF(B9="","",E9/$E$11)
A10: ITEM EXTRA | B10: 0 | C10: 1 | D10: =B9*1.21 | E10: =B9*1.105 | F10: =IF(B9="","",E9/$E$11) | H10: Total MO | I10: =I7*I8
A11: Total | B11: =SUM(B2:B10) | D11: =SUM(D2:D10) | E11: =SUM(E2:E10) | F11: =IF(F2="","",SUM(F2:F10))
H12: =+E10/7
K13: Sobre compra
A14: Desgloce | B14: C/IVA | C14: Desc | D14: Utilidad propuesta | E14: Total C /IVa | F14: Total Desc | G14: Total Base c recargo | K14: s/IVA | L14: c/IVA | M14: c/10,5%
A15: Total Perfiles | B15: =D2 | C15: =E2 | D15: 0.55 | E15: =B14*(1+$D14)+D5 | F15: =C14*(1+$D14)+E5 | G15: =F14*1.15/1.21 | K15: =B10 | L15: =B10*1.21 | M15: =B10*1.105
A16: Total accesorios | B16: =D3+D4 | C16: =E3+E4 | D16: 0.53 | E16: =B15*(1+$D15) | F16: =C15*(1+$D15) | G16: =F15*1.15/1.21 | K16: Rentabilidad s/variable | L16: =G28*1.105-L14 | M16: =F28-M14
A17: Total vidrios lamin | B17: =D6 | C17: =E6 | D17: 1 | E17: =B16*(1+$D16) | F17: =C16*(1+$D16) | G17: =F16*1.15/1.21
A18: Total vidrios crudos | B18: =D7 | C18: =E7 | D18: 0.8 | E18: =B17*(1+$D$17) | F18: =C17*(1+$D$17) | G18: =F17*1.15/1.21 | K18: Extras
A19: Total vidrial | B19: =D8 | C19: =E8 | D19: 0.5 | E19: =B18*(1+$D18) | F19: =C18*(1+$D18) | G19: =F18*1.15/1.21 | K19: Acristalamiento en altura
A20: Total tela mos | B20: =D9 | C20: =E9 | D20: 1 | E20: =B19*(1+$D19) | F20: =C19*(1+$D19) | G20: =F19*1.15/1.21
A21: Total | B21: =SUM(B14:B19) | C21: =SUM(C14:C19) | E21: =SUM(E14:E19) | F21: =SUM(F14:F19) | G21: =SUM(G14:G19) | N21: =270000
N22: 240000
A23: %Utilidad nec SOFT | B23: =IF(G28=0,"",(G28/B25*(1+B26)-1)) | E23: Total c/IVA | F23: Total Desc | G23: Base s/Iva | N23: =N21+N20
A24: Lista de precios | D24: Precios por defecto | E24: =F20*1.15 | F24: =E23/1.15 | G24: =E23/1.21
D25: Rentabilidad s/variable | E25: =E23/1.21*1.105-E10 | F25: =F23-$E$10 | H25: Margen%
A26: PNeto1 | B26: 0 | D26: %markup s/directo | E26: =E24/D10 | F26: =F24/E10 | H26: =F25/(1+F25)
A27: Utilidad1 | B27: 0
E28: Total c/IVA | F28: Total Desc | G28: Base s/Iva
D29: Precios enviados | E29: =G28*1.21 | F29: =E28/1.15 | G29: =G23
D30: Rentabilidad s/variable | E30: =E28/1.21*1.105-$E$10-SUM($E$6:$E$7)*$L$4 | F30: =F28-$E$10-SUM($E$6:$E$7)*$L$4 | H30: Margen%
D31: %markup s/directo | E31: =E29/$D$10 | F31: =F29/$E$10 | H31: =F30/(1+F30)
E33: Total c/IVA | F33: Total Desc | G33: Base s/Iva
D34: Precios enviados | E34: =G33*1.21 | F34: =G33*1.105 | G34: =G28
D35: Rentabilidad s/variable | E35: =E33/1.21*1.105-$E$10-SUM($E$6:$E$7)*$L$4 | F35: =F33-$E$10-SUM($E$6:$E$7)*$L$4 | H35: Margen%
D36: %markup s/directo | E36: =E34/$D$10 | F36: =F34/$E$10 | H36: =F35/(1+F35)
E38: Total c/IVA | F38: Total Desc | G38: Base s/Iva
D39: Precios enviados | E39: =G38*1.21 | F39: 9682520 | G39: =G33*0.95
D40: Rentabilidad s/variable | E40: =E38/1.21*1.105-$E$10-SUM($E$6:$E$7)*$L$4 | F40: =F38-$E$10-SUM($E$6:$E$7)*$L$4 | H40: Margen%
D41: %markup s/directo | E41: =E39/$D$10 | F41: =F39/$E$10 | H41: =F40/(1+F40)

Sheet Base perfiles
A1: 1 | B1: 2 | C1: 3 | D1: 4 | E1: 5 | F1: 6 | G1: 7 | H1: 8 | I1: 9 | J1: 10 | K1: 11 | L1: 12 | M1: 13 | N1: 14
A2: Código | B2: Descripción | C2: Largo STD | D2: Kg/m | E2: Kg/barra | F2: A s/IVA | G2: B s/IVA | H2: N s/IVA | I2: A c 10,5 | J2: B c 10,5 | K2: N c 10,5 | L2: A c/IVA | M2: B c/IVA | N2: N c/IVA
A3: 6 | B3: TABLILLA POSTIGON TROQUELADA | C3: 6030 | E3: =D3*C3/1000 | F3: =L3/1.21 | G3: =M3/1.21 | H3: =N3/1.21 | I3: =F3*1.105 | J3: =G3*1.105 | K3: =H3*1.105 | L3: 32502.54 | M3: 30172.14 | N3: 32411.68
A4: 200 | B4: NEGRO (A)" | C4: 6150 | D4: 1.266 | E4: =D4*C4/1000 | F4: =L4/1.21 | G4: =M4/1.21 | H4: =N4/1.21 | I4: =F4*1.105 | J4: =G4*1.105 | K4: =H4*1.105 | L4: 161735.16 | M4: 141534.4 | N4: 149334.79
A5: 201 | B5: NEGRO (A)" | C5: 6150 | D5: 0.662 | E5: =D5*C5/1000 | F5: =L5/1.21 | G5: =M5/1.21 | H5: =N5/1.21 | I5: =F5*1.105 | J5: =G5*1.105 | K5: =H5*1.105 | L5: 84577.1 | M5: 73972.07 | N5: 78048.9
A6: 203 | B6: NEGRO" | C6: 6150 | D6: 0.716 | E6: =D6*C6/1000 | F6: =L6/1.21 | G6: =M6/1.21 | H6: =N6/1.21 | I6: =F6*1.105 | J6: =G6*1.105 | K6: =H6*1.105 | L6: 83216.95 | M6: 72759.42 | N6: 76769.42
A7: 204 | B7: NEGRO (A)" | C7: 6030 | D7: 0.705 | E7: =D7*C7/1000 | F7: =L7/1.21 | G7: =M7/1.21 | H7: =N7/1.21 | I7: =F7*1.105 | J7: =G7*1.105 | K7: =H7*1.105 | L7: 88410.27 | M7: 77263.58 | N7: 81521.81
A8: 205 | B8: PREMARCO 37MM | C8: 6150 | D8: 0.327 | E8: =D8*C8/1000 | F8: =L8/1.21 | G8: =M8/1.21 | H8: =N8/1.21 | I8: =F8*1.105 | J8: =G8*1.105 | K8: =H8*1.105 | L8: 30866.79 | M8: 30866.79 | N8: 30866.79
A9: 206 | B9: NEGRO (A)" | C9: 6150 | D9: 0.184 | E9: =D9*C9/1000 | F9: =L9/1.21 | G9: =M9/1.21 | H9: =N9/1.21 | I9: =F9*1.105 | J9: =G9*1.105 | K9: =H9*1.105 | L9: 23617.29 | M9: 21308.12 | N9: 22482.47
A10: 207 | B10: NEGRO (A)" | C10: 6150 | D10: 0.613 | E10: =D10*C10/1000 | F10: =L10/1.21 | G10: =M10/1.21 | H10: =N10/1.21 | I10: =F10*1.105 | J10: =G10*1.105 | K10: =H10*1.105 | L10: 78394.57 | M10: 68601.75 | N10: 72382.59
A11: 209 | B11: ZOCALO ALTO | C11: 6030 | D11: 1.256 | E11: =D11*C11/1000 | F11: =L11/1.21 | G11: =M11/1.21 | H11: =N11/1.21 | I11: =F11*1.105 | J11: =G11*1.105 | K11: =H11*1.105 | L11: 157407.38 | M11: 145127.56 | N11: 150158
A12: 213 | B12: PERFIL DE ACOPLE | C12: 6030 | D12: 0.257 | E12: =D12*C12/1000 | F12: =L12/1.21 | G12: =M12/1.21 | H12: =N12/1.21 | I12: =F12*1.105 | J12: =G12*1.105 | K12: =H12*1.105 | L12: 32272.85 | M12: 30732.81 | N12: 29474.86
A13: 214 | B13: JAMBA Y CABEZAL HOJA PUERTA REBATIR | C13: 6150 | D13: 1.088 | E13: =D13*C13/1000 | F13: =L13/1.21 | G13: =M13/1.21 | H13: =N13/1.21 | I13: =F13*1.105 | J13: =G13*1.105 | K13: =H13*1.105 | L13: 139107.08 | M13: 117905.05 | N13: 132374
A14: 216 | B14: NEGRO (A)" | C14: 6150 | D14: 0.726 | E14: =D14*C14/1000 | F14: =L14/1.21 | G14: =M14/1.21 | H14: =N14/1.21 | I14: =F14*1.105 | J14: =G14*1.105 | K14: =H14*1.105 | L14: 92738.05 | M14: 81074.79 | N14: 85543.06
A15: 217 | B15: CONTRAVIDRIO 29MM | C15: 6030 | D15: 0.292 | E15: =D15*C15/1000 | F15: =L15/1.21 | G15: =M15/1.21 | H15: =N15/1.21 | I15: =F15*1.105 | J15: =G15*1.105 | K15: =H15*1.105 | L15: 33961.65 | M15: 25417.28 | N15: 30252.72
... A41: 260 | B41: HOJA DE VENTANA PROYECTANTE CURVA | C41: 6030 | D41: 1.099 | E41: =D41*C41/1000 | F41: =L41/1.21 | G41: =M41/1.21 | H41: =N41/1.21 | I41: =F41*1.105 | J41: =G41*1.105 | K41: =H41*1.105 | L41: 137746.89 | M41: 122931.62 | N41: 125852.42
A42: 261 | B42: COLUMNA DE ACOPLE REFORZADA | C42: 6150 | D42: 1.274 | E42: =D42*C42/1000 | F42: =L42/1.21 | G42: =M42/1.21 | H42: =N42/1.21 | I42: =F42*1.105 | J42: =G42*1.105 | K42: =H42*1.105 | L42: 149219.25 | N42: 143480.05
A43: 262 | B43: COLUMNA DE ACOPLE A 90 | C43: 6150 | D43: 0.68 | E43: =D43*C43/1000 | F43: =L43/1.21 | G43: =M43/1.21 | H43: =N43/1.21 | I43: =F43*1.105 | J43: =G43*1.105 | K43: =H43*1.105 | L43: 86926.47 | M43: 77088.74 | N43: 79246.38
A44: 265 | B44: COLUMNA DE ACOPLE A 135 | C44: 6150 | D44: 0.535 | E44: =D44*C44/1000 | F44: =L44/1.21 | G44: =M44/1.21 | H44: =N44/1.21 | I44: =F44*1.105 | J44: =G44*1.105 | K44: =H44*1.105 | L44: 68583.08 | N44: 62348.25
A45: 280 | B45: MARCO A 45 | C45: 6150 | D45: 1.193 | E45: =D45*C45/1000 | F45: =L45/1.21 | G45: =M45/1.21 | H45: =N45/1.21 | I45: =F45*1.105 | J45: =G45*1.105 | K45: =H45*1.105 | L45: 152461.35 | M45: 136590.6 | N45: 131189.11
A46: 281 | B46: MARCO VENTANA GUILLOTINA | C46: 6030 | D46: 1.058 | E46: =D46*C46/1000 | F46: =L46/1.21 | G46: =M46/1.21 | H46: =N46/1.21 | I46: =F46*1.105 | J46: =G46*1.105 | K46: =H46*1.105 | L46: 125035.79 | M46: 121917.41 | N46: 140726.8
A47: 282 | B47: TAPA COMPENSADORA GUILLOTINA | C47: 6030 | D47: 0.14 | E47: =D47*C47/1000 | F47: =L47/1.21 | G47: =M47/1.21 | H47: =N47/1.21 | I47: =F47*1.105 | J47: =G47*1.105 | K47: =H47*1.105 | L47: 15254.88 | M47: 14408.16 | N47: 18725.52
A48: 283 | B48: HOJA VENTANA GUILLOTINA | C48: 6030 | D48: 0.537 | E48: =D48*C48/1000 | F48: =L48/1.21 | G48: =M48/1.21 | H48: =N48/1.21 | I48: =F48*1.105 | J48: =G48*1.105 | K48: =H48*1.105 | L48: 91353.42 | M48: 62864.28 | N48: 68948.97
A49: 284 | B49: GUIA DE 3 HOJAS A 45 | C49: 6150 | D49: 1.647 | E49: =D49*C49/1000 | F49: =L49/1.21 | G49: =M49/1.21 | H49: =N49/1.21 | I49: =F49*1.105 | J49: =G49*1.105 | K49: =H49*1.105 | L49: 181771.89 | M49: 174108.35 | N49: 181055.29
A50: 315 | B50: SOLAPA CENTRAL | C50: 6200 | D50: 0.381 | E50: =D50*C50/1000 | F50: =L50/1.21 | G50: =M50/1.21 | H50: =N50/1.21 | I50: =F50*1.105 | J50: =G50*1.105 | K50: =H50*1.105 | L50: 46929.61 | M50: 40978.61 | N50: 40860.63
A51: 324 | B51: ENCUENTRO CENTRAL CORREDIZA 4 HOJAS 45 | C51: 6200 | D51: 0.208 | E51: =D51*C51/1000 | F51: =L51/1.21 | G51: =M51/1.21 | H51: =N51/1.21 | I51: =F51*1.105 | J51: =G51*1.105 | K51: =H51*1.105 | L51: 23427.1 | M51: 23246.36 | N51: 23334.31
A52: 325 | B52: HOJA PERIMETRAL PARA VIDRIO SIMPLE | C52: 6200 | D52: 0.824 | E52: =D52*C52/1000 | F52: =L52/1.21 | G52: =M52/1.21 | H52: =N52/1.21 | I52: =F52*1.105 | J52: =G52*1.105 | K52: =H52*1.105 | L52: 106215.98 | M52: 87840.97 | N52: 94112.34
A53: 326 | B53: MOSQUITERO REFORZADO (L/R60) - MDT | C53: 6200 | D53: 0.617 | E53: =D53*C53/1000 | F53: =L53/1.21 | G53: =M53/1.21 | H53: =N53/1.21 | I53: =F53*1.105 | J53: =G53*1.105 | K53: =H53*1.105 | L53: 82751.42 | M53: 78679.79 | N53: 82063.81
A54: 383 | B54: HOJA PERIMETRAL PARA DVH | C54: 6200 | D54: 0.797 | E54: =D54*C54/1000 | F54: =L54/1.21 | G54: =M54/1.21 | H54: =N54/1.21 | I54: =F54*1.105 | J54: =G54*1.105 | K54: =H54*1.105 | L54: 94173.77 | M54: 88922.07 | N54: 94112.36
A55: 397 | B55: HOJA PUERTA CORREDIZA R6045 | C55: 6200 | D55: 1.37 | E55: =D55*C55/1000 | F55: =L55/1.21 | G55: =M55/1.21 | H55: =N55/1.21 | I55: =F55*1.105 | J55: =G55*1.105 | K55: =H55*1.105 | L55: 178371.3 | M55: 168596.68 | N55: 177401.4
A56: 401 | B56: ACOPLE 180 60MM MASSR60 | C56: 6200 | E56: =D56*C56/1000 | F56: =L56/1.21 | G56: =M56/1.21 | H56: =N56/1.21 | I56: =F56*1.105 | J56: =G56*1.105 | K56: =H56*1.105 | L56: 37821.97 | M56: 45119.88 | N56: 37474.56
A57: 402 | B57: SOLAPA CENTRAL R6045 | C57: 6200 | D57: 0.429 | E57: =D57*C57/1000 | F57: =L57/1.21 | G57: =M57/1.21 | H57: =N57/1.21 | I57: =F57*1.105 | J57: =G57*1.105 | K57: =H57*1.105 | L57: 54976.29 | M57: 48392.93 | N57: 51532.39
A58: 615 | B58: ADAPTADOR VS R6045 | C58: 6200 | D58: 0.246 | E58: =D58*C58/1000 | F58: =L58/1.21 | G58: =M58/1.21 | H58: =N58/1.21 | I58: =F58*1.105 | J58: =G58*1.105 | K58: =H58*1.105 | L58: 31501.84 | M58: 27110.71 | N58: 29550.3
A59: 619 | B59: HOJA VENTANA CORREDIZA 45 | C59: 6200 | E59: =D59*C59/1000 | F59: =L59/1.21 | G59: =M59/1.21 | H59: =N59/1.21 | I59: =F59*1.105 | J59: =G59*1.105 | K59: =H59*1.105 | L59: 140279.77 | M59: 124498.74 | N59: 134296.77
A60: 621 | B60: SOLAPA CENTRAL R6045 619 | C60: 6200 | E60: =D60*C60/1000 | F60: =L60/1.21 | G60: =M60/1.21 | H60: =N60/1.21 | I60: =F60*1.105 | J60: =G60*1.105 | K60: =H60*1.105 | L60: 52598.7 | M60: 46600.54 | N60: 48649.32
A61: 816 | B61: COLUMNA 120MM FRENTE INTEGRAL | C61: 6030 | E61: =D61*C61/1000 | F61: =L61/1.21 | G61: =M61/1.21 | H61: =N61/1.21 | I61: =F61*1.105 | J61: =G61*1.105 | K61: =H61*1.105 | L61: 244186.53
A62: 817 | B62: COLUMNA 60MM FRENTE INTEGRAL | C62: 6030 | E62: =D62*C62/1000 | F62: =L62/1.21 | G62: =M62/1.21 | H62: =N62/1.21 | I62: =F62*1.105 | J62: =G62*1.105 | K62: =H62*1.105 | L62: 137194.54 | M62: 125827.54 | N62: 133073.29
A63: 818 | B63: TAPA COLUMNA FRENTE INTEGRAL | C63: 6030 | E63: =D63*C63/1000 | F63: =L63/1.21 | G63: =M63/1.21 | H63: =N63/1.21 | I63: =F63*1.105 | J63: =G63*1.105 | K63: =H63*1.105 | L63: 45873.59 | N63: 41194.95
A64: 819 | B64: PRESOR FRENTE INTEGRAL | C64: 6030 | E64: =D64*C64/1000 | F64: =L64/1.21 | G64: =M64/1.21 | H64: =N64/1.21 | I64: =F64*1.105 | J64: =G64*1.105 | K64: =H64*1.105 | L64: 43113.23 | M64: 43113.23 | N64: 43113.23
A65: 821 | B65: FRRENTE INTEGRAL COLUMNA 140mm | C65: 6030 | E65: =D65*C65/1000 | F65: =L65/1.21 | G65: =M65/1.21 | H65: =N65/1.21 | I65: =F65*1.105 | J65: =G65*1.105 | K65: =H65*1.105 | L65: 279738.8 | M65: 273565.43 | N65: 295693.09
...

Sheet Base vidrios
B3: VIDRIO | C3: PRECIO (M2) | E3: CAMARA | F3: PRECIO (ML) | H3: Valvula | I3: Precio
B4: FLOAT4 | C4: 16110 | E4: 6 | F4: 4760 | H4: SI | I4: 6500
B5: T4 | C5: 29590 | E5: 9 | F5: 4910 | H5: NO | I5: 0
B6: T5 | C6: 33370 | E6: 12 | F6: 6160
B7: T6 | C7: 36150 | E7: 9p | F7: 2018.0995
B8: T8 | C8: 44170 | E8: 15 | F8: 10060
B9: T10 | C9: 50640 | E9: 0 | F9: 0
B10: LAMIN3+3 | C10: 40030
B11: LAMIN3+3OP | C11: 70660
B12: VIDRIO | C12: 0
B13: SN6mm | C13: 55630
B14: CL6mm | C14: 87000
B15: P4 | C15: 27070
B16: FLOAT4p | C16: 11525
B17: LAMIN3+3p | C17: 29808.235

Sheet Plantilla Retazo
B3: Codigo | C3: Color | D3: Largo retazo | E3: Cantidad | F3: Bonificacion | G3: Precio barra | H3: Precio retazo | J3: Total retazo | K3: Total retazo S/IVA | N3: Codigo | O3: Color | P3: Largo retazo | Q3: Cantidad | R3: Bonificacion | S3: Precio barra | T3: Precio retazo | V3: Total retazo | W3: Total retazo S/IVA
B4: 200 | C4: Negro | D4: 4792 | E4: 0 | F4: 0.1 | G4: =IF(B4="","",IF(C4="negro",VLOOKUP(B4,'Base perfiles'!$A$3:$O$200,8,),IF(C4="blanco",VLOOKUP(B4,'Base perfiles'!$A$3:$O$200,7),IF(C4="ANODIZADO",VLOOKUP(B4,'Base perfiles'!$A$3:$O$200,6))))) | H4: =IF(G4="","",D4*E4/VLOOKUP(B4,'Base perfiles'!$A$3:$O$200,3,)*G4*(1-F4)*1.105) | J4: =SUM(Tabla_1[Precio retazo]) | K4: =J4/1.105 | N4: 6501 | O4: Negro | P4: 2920 | Q4: 0 | R4: 0.1 | S4: =IF(N4="","",IF(O4="negro",VLOOKUP(N4,'Base perfiles'!$A$3:$O$200,8,),IF(O4="blanco",VLOOKUP(N4,'Base perfiles'!$A$3:$O$200,7),IF(O4="ANODIZADO",VLOOKUP(N4,'Base perfiles'!$A$3:$O$200,6))))) | T4: =IF(S4="","",P4*Q4/VLOOKUP(N4,'Base perfiles'!$A$3:$O$200,3,)*S4*(1-R4)*1.105) | V4: =SUM(Tabla_7[Precio retazo]) | W4: =V4/1.105
B5: 201 | C5: Negro | D5: 2745 | E5: 0 | F5: 0.1 | G5: =IF(B5="","",IF(C5="negro",VLOOKUP(B5,'Base perfiles'!$A$3:$O$200,8,),IF(C5="blanco",VLOOKUP(B5,'Base perfiles'!$A$3:$O$200,7),IF(C5="ANODIZADO",VLOOKUP(B5,'Base perfiles'!$A$3:$O$200,6))))) | H5: =IF(G5="","",D5*E5/VLOOKUP(B5,'Base perfiles'!$A$3:$O$200,3,)*G5*(1-F5)*1.105) | N5: 6502 | O5: Negro | P5: 2920 | Q5: 0 | R5: 0.1 | S5: =IF(N5="","",IF(O5="negro",VLOOKUP(N5,'Base perfiles'!$A$3:$O$200,8,),IF(O5="blanco",VLOOKUP(N5,'Base perfiles'!$A$3:$O$200,7),IF(O5="ANODIZADO",VLOOKUP(N5,'Base perfiles'!$A$3:$O$200,6))))) | T5: =IF(S5="","",P5*Q5/VLOOKUP(N5,'Base perfiles'!$A$3:$O$200,3,)*S5*(1-R5)*1.105)
B6: 203 | C6: Negro | D6: 4051 | E6: 0 | F6: 0.1 | G6: =IF(B6="","",IF(C6="negro",VLOOKUP(B6,'Base perfiles'!$A$3:$O$200,8,),IF(C6="blanco",VLOOKUP(B6,'Base perfiles'!$A$3:$O$200,7),IF(C6="ANODIZADO",VLOOKUP(B6,'Base perfiles'!$A$3:$O$200,6))))) | H6: =IF(G6="","",D6*E6/VLOOKUP(B6,'Base perfiles'!$A$3:$O$200,3,)*G6*(1-F6)*1.105) | N6: 6512 | O6: Negro | P6: 4643 | Q6: 0 | R6: 0.1 | S6: =IF(N6="","",IF(O6="negro",VLOOKUP(N6,'Base perfiles'!$A$3:$O$200,8,),IF(O6="blanco",VLOOKUP(N6,'Base perfiles'!$A$3:$O$200,7),IF(O6="ANODIZADO",VLOOKUP(N6,'Base perfiles'!$A$3:$O$200,6))))) | T6: =IF(S6="","",P6*Q6/VLOOKUP(N6,'Base perfiles'!$A$3:$O$200,3,)*S6*(1-R6)*1.105)
B7: 206 | C7: Negro | D7: 3696 | E7: 0 | F7: 0.1 | G7: =IF(B7="","",IF(C7="negro",VLOOKUP(B7,'Base perfiles'!$A$3:$O$200,8,),IF(C7="blanco",VLOOKUP(B7,'Base perfiles'!$A$3:$O$200,7),IF(C7="ANODIZADO",VLOOKUP(B7,'Base perfiles'!$A$3:$O$200,6))))) | H7: =IF(G7="","",D7*E7/VLOOKUP(B7,'Base perfiles'!$A$3:$O$200,3,)*G7*(1-F7)*1.105) | N7: 6513 | O7: Negro | P7: 4643 | Q7: 0 | R7: 0.1 | S7: =IF(N7="","",IF(O7="negro",VLOOKUP(N7,'Base perfiles'!$A$3:$O$200,8,),IF(O7="blanco",VLOOKUP(N7,'Base perfiles'!$A$3:$O$200,7),IF(O7="ANODIZADO",VLOOKUP(N7,'Base perfiles'!$A$3:$O$200,6))))) | T7: =IF(S7="","",P7*Q7/VLOOKUP(N7,'Base perfiles'!$A$3:$O$200,3,)*S7*(1-R7)*1.105)
B8: 207 | C8: Negro | D8: 4051 | E8: 0 | F8: 0.1 | G8: =IF(B8="","",IF(C8="negro",VLOOKUP(B8,'Base perfiles'!$A$3:$O$200,8,),IF(C8="blanco",VLOOKUP(B8,'Base perfiles'!$A$3:$O$200,7),IF(C8="ANODIZADO",VLOOKUP(B8,'Base perfiles'!$A$3:$O$200,6))))) | H8: =IF(G8="","",D8*E8/VLOOKUP(B8,'Base perfiles'!$A$3:$O$200,3,)*G8*(1-F8)*1.105) | N8: 6514 | O8: Negro | P8: 3686 | Q8: 0 | R8: 0.1 | S8: =IF(N8="","",IF(O8="negro",VLOOKUP(N8,'Base perfiles'!$A$3:$O$200,8,),IF(O8="blanco",VLOOKUP(N8,'Base perfiles'!$A$3:$O$200,7),IF(O8="ANODIZADO",VLOOKUP(N8,'Base perfiles'!$A$3:$O$200,6))))) | T8: =IF(S8="","",P8*Q8/VLOOKUP(N8,'Base perfiles'!$A$3:$O$200,3,)*S8*(1-R8)*1.105)
B9: 213 | C9: Negro | D9: 5430 | E9: 0 | F9: 0.1 | G9: =IF(B9="","",IF(C9="negro",VLOOKUP(B9,'Base perfiles'!$A$3:$O$200,8,),IF(C9="blanco",VLOOKUP(B9,'Base perfiles'!$A$3:$O$200,7),IF(C9="ANODIZADO",VLOOKUP(B9,'Base perfiles'!$A$3:$O$200,6))))) | H9: =IF(G9="","",D9*E9/VLOOKUP(B9,'Base perfiles'!$A$3:$O$200,3,)*G9*(1-F9)*1.105) | R9: 0.1 | S9: =IF(N9="","",IF(O9="negro",VLOOKUP(N9,'Base perfiles'!$A$3:$O$200,8,),IF(O9="blanco",VLOOKUP(N9,'Base perfiles'!$A$3:$O$200,7),IF(O9="ANODIZADO",VLOOKUP(N9,'Base perfiles'!$A$3:$O$200,6))))) | T9: =IF(S9="","",P9*Q9/VLOOKUP(N9,'Base perfiles'!$A$3:$O$200,3,)*S9*(1-R9)*1.105)
B10: 216 | C10: Negro | D10: 3897 | E10: 0 | F10: 0.1 | G10: =IF(B10="","",IF(C10="negro",VLOOKUP(B10,'Base perfiles'!$A$3:$O$200,8,),IF(C10="blanco",VLOOKUP(B10,'Base perfiles'!$A$3:$O$200,7),IF(C10="ANODIZADO",VLOOKUP(B10,'Base perfiles'!$A$3:$O$200,6))))) | H10: =IF(G10="","",D10*E10/VLOOKUP(B10,'Base perfiles'!$A$3:$O$200,3,)*G10*(1-F10)*1.105) | K10: =SUM(H17:H19)/1.105 | R10: 0.1 | S10: =IF(N10="","",IF(O10="negro",VLOOKUP(N10,'Base perfiles'!$A$3:$O$200,8,),IF(O10="blanco",VLOOKUP(N10,'Base perfiles'!$A$3:$O$200,7),IF(O10="ANODIZADO",VLOOKUP(N10,'Base perfiles'!$A$3:$O$200,6))))) | T10: =IF(S10="","",P10*Q10/VLOOKUP(N10,'Base perfiles'!$A$3:$O$200,3,)*S10*(1-R10)*1.105)
B11: 217 | C11: Negro | D11: 4263 | E11: 0 | F11: 0.1 | G11: =IF(B11="","",IF(C11="negro",VLOOKUP(B11,'Base perfiles'!$A$3:$O$200,8,),IF(C11="blanco",VLOOKUP(B11,'Base perfiles'!$A$3:$O$200,7),IF(C11="ANODIZADO",VLOOKUP(B11,'Base perfiles'!$A$3:$O$200,6))))) | H11: =IF(G11="","",D11*E11/VLOOKUP(B11,'Base perfiles'!$A$3:$O$200,3,)*G11*(1-F11)*1.105) | R11: 0.1 | S11: =IF(N11="","",IF(O11="negro",VLOOKUP(N11,'Base perfiles'!$A$3:$O$200,8,),IF(O11="blanco",VLOOKUP(N11,'Base perfiles'!$A$3:$O$200,7),IF(O11="ANODIZADO",VLOOKUP(N11,'Base perfiles'!$A$3:$O$200,6))))) | T11: =IF(S11="","",P11*Q11/VLOOKUP(N11,'Base perfiles'!$A$3:$O$200,3,)*S11*(1-R11)*1.105)
B12: 219 | C12: Negro | D12: 4807 | E12: 0 | F12: 0.1 | G12: =IF(B12="","",IF(C12="negro",VLOOKUP(B12,'Base perfiles'!$A$3:$O$200,8,),IF(C12="blanco",VLOOKUP(B12,'Base perfiles'!$A$3:$O$200,7),IF(C12="ANODIZADO",VLOOKUP(B12,'Base perfiles'!$A$3:$O$200,6))))) | H12: =IF(G12="","",D12*E12/VLOOKUP(B12,'Base perfiles'!$A$3:$O$200,3,)*G12*(1-F12)*1.105) | R12: 0.1 | S12: =IF(N12="","",IF(O12="negro",VLOOKUP(N12,'Base perfiles'!$A$3:$O$200,8,),IF(O12="blanco",VLOOKUP(N12,'Base perfiles'!$A$3:$O$200,7),IF(O12="ANODIZADO",VLOOKUP(N12,'Base perfiles'!$A$3:$O$200,6))))) | T12: =IF(S12="","",P12*Q12/VLOOKUP(N12,'Base perfiles'!$A$3:$O$200,3,)*S12*(1-R12)*1.105)
B13: 230 | C13: Negro | D13: 5350 | E13: 0 | F13: 0.1 | G13: =IF(B13="","",IF(C13="negro",VLOOKUP(B13,'Base perfiles'!$A$3:$O$200,8,),IF(C13="blanco",VLOOKUP(B13,'Base perfiles'!$A$3:$O$200,7),IF(C13="ANODIZADO",VLOOKUP(B13,'Base perfiles'!$A$3:$O$200,6))))) | H13: =IF(G13="","",D13*E13/VLOOKUP(B13,'Base perfiles'!$A$3:$O$200,3,)*G13*(1-F13)*1.105) | R13: 0.1 | S13: =IF(N13="","",IF(O13="negro",VLOOKUP(N13,'Base perfiles'!$A$3:$O$200,8,),IF(O13="blanco",VLOOKUP(N13,'Base perfiles'!$A$3:$O$200,7),IF(O13="ANODIZADO",VLOOKUP(N13,'Base perfiles'!$A$3:$O$200,6))))) | T13: =IF(S13="","",P13*Q13/VLOOKUP(N13,'Base perfiles'!$A$3:$O$200,3,)*S13*(1-R13)*1.105)
B14: 248 | C14: Negro | D14: 1277 | E14: 0 | F14: 0.1 | G14: =IF(B14="","",IF(C14="negro",VLOOKUP(B14,'Base perfiles'!$A$3:$O$200,8,),IF(C14="blanco",VLOOKUP(B14,'Base perfiles'!$A$3:$O$200,7),IF(C14="ANODIZADO",VLOOKUP(B14,'Base perfiles'!$A$3:$O$200,6))))) | H14: =IF(G14="","",D14*E14/VLOOKUP(B14,'Base perfiles'!$A$3:$O$200,3,)*G14*(1-F14)*1.105) | R14: 0.1 | S14: =IF(N14="","",IF(O14="negro",VLOOKUP(N14,'Base perfiles'!$A$3:$O$200,8,),IF(O14="blanco",VLOOKUP(N14,'Base perfiles'!$A$3:$O$200,7),IF(O14="ANODIZADO",VLOOKUP(N14,'Base perfiles'!$A$3:$O$200,6))))) | T14: =IF(S14="","",P14*Q14/VLOOKUP(N14,'Base perfiles'!$A$3:$O$200,3,)*S14*(1-R14)*1.105)
B15: 248 | C15: Negro | D15: 4529 | E15: 0 | F15: 0.1 | G15: =IF(B15="","",IF(C15="negro",VLOOKUP(B15,'Base perfiles'!$A$3:$O$200,8,),IF(C15="blanco",VLOOKUP(B15,'Base perfiles'!$A$3:$O$200,7),IF(C15="ANODIZADO",VLOOKUP(B15,'Base perfiles'!$A$3:$O$200,6))))) | H15: =IF(G15="","",D15*E15/VLOOKUP(B15,'Base perfiles'!$A$3:$O$200,3,)*G15*(1-F15)*1.105) | R15: 0.1 | S15: =IF(N15="","",IF(O15="negro",VLOOKUP(N15,'Base perfiles'!$A$3:$O$200,8,),IF(O15="blanco",VLOOKUP(N15,'Base perfiles'!$A$3:$O$200,7),IF(O15="ANODIZADO",VLOOKUP(N15,'Base perfiles'!$A$3:$O$200,6))))) | T15: =IF(S15="","",P15*Q15/VLOOKUP(N15,'Base perfiles'!$A$3:$O$200,3,)*S15*(1-R15)*1.105)
B16: 249 | C16: Negro | D16: 4075 | E16: 0 | F16: 0.1 | G16: =IF(B16="","",IF(C16="negro",VLOOKUP(B16,'Base perfiles'!$A$3:$O$200,8,),IF(C16="blanco",VLOOKUP(B16,'Base perfiles'!$A$3:$O$200,7),IF(C16="ANODIZADO",VLOOKUP(B16,'Base perfiles'!$A$3:$O$200,6))))) | H16: =IF(G16="","",D16*E16/VLOOKUP(B16,'Base perfiles'!$A$3:$O$200,3,)*G16*(1-F16)*1.105) | R16: 0.1 | S16: =IF(N16="","",IF(O16="negro",VLOOKUP(N16,'Base perfiles'!$A$3:$O$200,8,),IF(O16="blanco",VLOOKUP(N16,'Base perfiles'!$A$3:$O$200,7),IF(O16="ANODIZADO",VLOOKUP(N16,'Base perfiles'!$A$3:$O$200,6))))) | T16: =IF(S16="","",P16*Q16/VLOOKUP(N16,'Base perfiles'!$A$3:$O$200,3,)*S16*(1-R16)*1.105)
B17: 250 | C17: Negro | D17: 1277 | E17: 0 | F17: 0.1 | G17: =IF(B17="","",IF(C17="negro",VLOOKUP(B17,'Base perfiles'!$A$3:$O$200,8,),IF(C17="blanco",VLOOKUP(B17,'Base perfiles'!$A$3:$O$200,7),IF(C17="ANODIZADO",VLOOKUP(B17,'Base perfiles'!$A$3:$O$200,6))))) | H17: =IF(G17="","",D17*E17/VLOOKUP(B17,'Base perfiles'!$A$3:$O$200,3,)*G17*(1-F17)*1.105) | R17: 0.1 | S17: =IF(N17="","",IF(O17="negro",VLOOKUP(N17,'Base perfiles'!$A$3:$O$200,8,),IF(O17="blanco",VLOOKUP(N17,'Base perfiles'!$A$3:$O$200,7),IF(O17="ANODIZADO",VLOOKUP(N17,'Base perfiles'!$A$3:$O$200,6))))) | T17: =IF(S17="","",P17*Q17/VLOOKUP(N17,'Base perfiles'!$A$3:$O$200,3,)*S17*(1-R17)*1.105)
B18: 250 | C18: Negro | D18: 4529 | E18: 0 | F18: 0.1 | G18: =IF(B18="","",IF(C18="negro",VLOOKUP(B18,'Base perfiles'!$A$3:$O$200,8,),IF(C18="blanco",VLOOKUP(B18,'Base perfiles'!$A$3:$O$200,7),IF(C18="ANODIZADO",VLOOKUP(B18,'Base perfiles'!$A$3:$O$200,6))))) | H18: =IF(G18="","",D18*E18/VLOOKUP(B18,'Base perfiles'!$A$3:$O$200,3,)*G18*(1-F18)*1.105) | R18: 0.1 | S18: =IF(N18="","",IF(O18="negro",VLOOKUP(N18,'Base perfiles'!$A$3:$O$200,8,),IF(O18="blanco",VLOOKUP(N18,'Base perfiles'!$A$3:$O$200,7),IF(O18="ANODIZADO",VLOOKUP(N18,'Base perfiles'!$A$3:$O$200,6))))) | T18: =IF(S18="","",P18*Q18/VLOOKUP(N18,'Base perfiles'!$A$3:$O$200,3,)*S18*(1-R18)*1.105)
F19: 0.1 | G19: =IF(B19="","",IF(C19="negro",VLOOKUP(B19,'Base perfiles'!$A$3:$O$200,8,),IF(C19="blanco",VLOOKUP(B19,'Base perfiles'!$A$3:$O$200,7),IF(C19="ANODIZADO",VLOOKUP(B19,'Base perfiles'!$A$3:$O$200,6))))) | H19: =IF(G19="","",D19*E19/VLOOKUP(B19,'Base perfiles'!$A$3:$O$200,3,)*G19*(1-F19)*1.105) | R19: 0.1 | S19: =IF(N19="","",IF(O19="negro",VLOOKUP(N19,'Base perfiles'!$A$3:$O$200,8,),IF(O19="blanco",VLOOKUP(N19,'Base perfiles'!$A$3:$O$200,7),IF(O19="ANODIZADO",VLOOKUP(N19,'Base perfiles'!$A$3:$O$200,6))))) | T19: =IF(S19="","",P19*Q19/VLOOKUP(N19,'Base perfiles'!$A$3:$O$200,3,)*S19*(1-R19)*1.105)
F20: 0.1 | G20: =IF(B20="","",IF(C20="negro",VLOOKUP(B20,'Base perfiles'!$A$3:$O$200,8,),IF(C20="blanco",VLOOKUP(B20,'Base perfiles'!$A$3:$O$200,7),IF(C20="ANODIZADO",VLOOKUP(B20,'Base perfiles'!$A$3:$O$200,6))))) | H20: =IF(G20="","",D20*E20/VLOOKUP(B20,'Base perfiles'!$A$3:$O$200,3,)*G20*(1-F20)*1.105) | R20: 0.1 | S20: =IF(N20="","",IF(O20="negro",VLOOKUP(N20,'Base perfiles'!$A$3:$O$200,8,),IF(O20="blanco",VLOOKUP(N20,'Base perfiles'!$A$3:$O$200,7),IF(O20="ANODIZADO",VLOOKUP(N20,'Base perfiles'!$A$3:$O$200,6))))) | T20: =IF(S20="","",P20*Q20/VLOOKUP(N20,'Base perfiles'!$A$3:$O$200,3,)*S20*(1-R20)*1.105)
F21: 0.1 | G21: =IF(B21="","",IF(C21="negro",VLOOKUP(B21,'Base perfiles'!$A$3:$O$200,8,),IF(C21="blanco",VLOOKUP(B21,'Base perfiles'!$A$3:$O$200,7),IF(C21="ANODIZADO",VLOOKUP(B21,'Base perfiles'!$A$3:$O$200,6))))) | H21: =IF(G21="","",D21*E21/VLOOKUP(B21,'Base perfiles'!$A$3:$O$200,3,)*G21*(1-F21)*1.105) | R21: 0.1 | S21: =IF(N21="","",IF(O21="negro",VLOOKUP(N21,'Base perfiles'!$A$3:$O$200,8,),IF(O21="blanco",VLOOKUP(N21,'Base perfiles'!$A$3:$O$200,7),IF(O21="ANODIZADO",VLOOKUP(N21,'Base perfiles'!$A$3:$O$200,6))))) | T21: =IF(S21="","",P21*Q21/VLOOKUP(N21,'Base perfiles'!$A$3:$O$200,3,)*S21*(1-R21)*1.105)
F22: 0.1 | G22: =IF(B22="","",IF(C22="negro",VLOOKUP(B22,'Base perfiles'!$A$3:$O$200,8,),IF(C22="blanco",VLOOKUP(B22,'Base perfiles'!$A$3:$O$200,7),IF(C22="ANODIZADO",VLOOKUP(B22,'Base perfiles'!$A$3:$O$200,6))))) | H22: =IF(G22="","",D22*E22/VLOOKUP(B22,'Base perfiles'!$A$3:$O$200,3,)*G22*(1-F22)*1.105) | R22: 0.1 | S22: =IF(N22="","",IF(O22="negro",VLOOKUP(N22,'Base perfiles'!$A$3:$O$200,8,),IF(O22="blanco",VLOOKUP(N22,'Base perfiles'!$A$3:$O$200,7),IF(O22="ANODIZADO",VLOOKUP(N22,'Base perfiles'!$A$3:$O$200,6))))) | T22: =IF(S22="","",P22*Q22/VLOOKUP(N22,'Base perfiles'!$A$3:$O$200,3,)*S22*(1-R22)*1.105)
F23: 0.1 | G23: =IF(B23="","",IF(C23="negro",VLOOKUP(B23,'Base perfiles'!$A$3:$O$200,8,),IF(C23="blanco",VLOOKUP(B23,'Base perfiles'!$A$3:$O$200,7),IF(C23="ANODIZADO",VLOOKUP(B23,'Base perfiles'!$A$3:$O$200,6))))) | H23: =IF(G23="","",D23*E23/VLOOKUP(B23,'Base perfiles'!$A$3:$O$200,3,)*G23*(1-F23)*1.105) | R23: 0.1 | S23: =IF(N23="","",IF(O23="negro",VLOOKUP(N23,'Base perfiles'!$A$3:$O$200,8,),IF(O23="blanco",VLOOKUP(N23,'Base perfiles'!$A$3:$O$200,7),IF(O23="ANODIZADO",VLOOKUP(N23,'Base perfiles'!$A$3:$O$200,6))))) | T23: =IF(S23="","",P23*Q23/VLOOKUP(N23,'Base perfiles'!$A$3:$O$200,3,)*S23*(1-R23)*1.105)
F24: 0.1 | G24: =IF(B24="","",IF(C24="negro",VLOOKUP(B24,'Base perfiles'!$A$3:$O$200,8,),IF(C24="blanco",VLOOKUP(B24,'Base perfiles'!$A$3:$O$200,7),IF(C24="ANODIZADO",VLOOKUP(B24,'Base perfiles'!$A$3:$O$200,6))))) | H24: =IF(G24="","",D24*E24/VLOOKUP(B24,'Base perfiles'!$A$3:$O$200,3,)*G24*(1-F24)*1.105) | R24: 0.1 | S24: =IF(N24="","",IF(O24="negro",VLOOKUP(N24,'Base perfiles'!$A$3:$O$200,8,),IF(O24="blanco",VLOOKUP(N24,'Base perfiles'!$A$3:$O$200,7),IF(O24="ANODIZADO",VLOOKUP(N24,'Base perfiles'!$A$3:$O$200,6))))) | T24: =IF(S24="","",P24*Q24/VLOOKUP(N24,'Base perfiles'!$A$3:$O$200,3,)*S24*(1-R24)*1.105)
F25: 0.1 | G25: =IF(B25="","",IF(C25="negro",VLOOKUP(B25,'Base perfiles'!$A$3:$O$200,8,),IF(C25="blanco",VLOOKUP(B25,'Base perfiles'!$A$3:$O$200,7),IF(C25="ANODIZADO",VLOOKUP(B25,'Base perfiles'!$A$3:$O$200,6))))) | H25: =IF(G25="","",D25*E25/VLOOKUP(B25,'Base perfiles'!$A$3:$O$200,3,)*G25*(1-F25)*1.105) | R25: 0.1 | S25: =IF(N25="","",IF(O25="negro",VLOOKUP(N25,'Base perfiles'!$A$3:$O$200,8,),IF(O25="blanco",VLOOKUP(N25,'Base perfiles'!$A$3:$O$200,7),IF(O25="ANODIZADO",VLOOKUP(N25,'Base perfiles'!$A$3:$O$200,6))))) | T25: =IF(S25="","",P25*Q25/VLOOKUP(N25,'Base perfiles'!$A$3:$O$200,3,)*S25*(1-R25)*1.105)
F26: 0.1 | G26: =IF(B26="","",IF(C26="negro",VLOOKUP(B26,'Base perfiles'!$A$3:$O$200,8,),IF(C26="blanco",VLOOKUP(B26,'Base perfiles'!$A$3:$O$200,7),IF(C26="ANODIZADO",VLOOKUP(B26,'Base perfiles'!$A$3:$O$200,6))))) | H26: =IF(G26="","",D26*E26/VLOOKUP(B26,'Base perfiles'!$A$3:$O$200,3,)*G26*(1-F26)*1.105) | R26: 0.1 | S26: =IF(N26="","",IF(O26="negro",VLOOKUP(N26,'Base perfiles'!$A$3:$O$200,8,),IF(O26="blanco",VLOOKUP(N26,'Base perfiles'!$A$3:$O$200,7),IF(O26="ANODIZADO",VLOOKUP(N26,'Base perfiles'!$A$3:$O$200,6))))) | T26: =IF(S26="","",P26*Q26/VLOOKUP(N26,'Base perfiles'!$A$3:$O$200,3,)*S26*(1-R26)*1.105)
F27: 0.1 | G27: =IF(B27="","",IF(C27="negro",VLOOKUP(B27,'Base perfiles'!$A$3:$O$200,8,),IF(C27="blanco",VLOOKUP(B27,'Base perfiles'!$A$3:$O$200,7),IF(C27="ANODIZADO",VLOOKUP(B27,'Base perfiles'!$A$3:$O$200,6))))) | H27: =IF(G27="","",D27*E27/VLOOKUP(B27,'Base perfiles'!$A$3:$O$200,3,)*G27*(1-F27)*1.105) | R27: 0.1 | S27: =IF(N27="","",IF(O27="negro",VLOOKUP(N27,'Base perfiles'!$A$3:$O$200,8,),IF(O27="blanco",VLOOKUP(N27,'Base perfiles'!$A$3:$O$200,7),IF(O27="ANODIZADO",VLOOKUP(N27,'Base perfiles'!$A$3:$O$200,6))))) | T27: =IF(S27="","",P27*Q27/VLOOKUP(N27,'Base perfiles'!$A$3:$O$200,3,)*S27*(1-R27)*1.105)
F28: 0.1 | G28: =IF(B28="","",IF(C28="negro",VLOOKUP(B28,'Base perfiles'!$A$3:$O$200,8,),IF(C28="blanco",VLOOKUP(B28,'Base perfiles'!$A$3:$O$200,7),IF(C28="ANODIZADO",VLOOKUP(B28,'Base perfiles'!$A$3:$O$200,6))))) | H28: =IF(G28="","",D28*E28/VLOOKUP(B28,'Base perfiles'!$A$3:$O$200,3,)*G28*(1-F28)*1.105) | R28: 0.1 | S28: =IF(N28="","",IF(O28="negro",VLOOKUP(N28,'Base perfiles'!$A$3:$O$200,8,),IF(O28="blanco",VLOOKUP(N28,'Base perfiles'!$A$3:$O$200,7),IF(O28="ANODIZADO",VLOOKUP(N28,'Base perfiles'!$A$3:$O$200,6))))) | T28: =IF(S28="","",P28*Q28/VLOOKUP(N28,'Base perfiles'!$A$3:$O$200,3,)*S28*(1-R28)*1.105)
F29: 0.1 | G29: =IF(B29="","",IF(C29="negro",VLOOKUP(B29,'Base perfiles'!$A$3:$O$200,8,),IF(C29="blanco",VLOOKUP(B29,'Base perfiles'!$A$3:$O$200,7),IF(C29="ANODIZADO",VLOOKUP(B29,'Base perfiles'!$A$3:$O$200,6))))) | H29: =IF(G29="","",D29*E29/VLOOKUP(B29,'Base perfiles'!$A$3:$O$200,3,)*G29*(1-F29)*1.105) | R29: 0.1 | S29: =IF(N29="","",IF(O29="negro",VLOOKUP(N29,'Base perfiles'!$A$3:$O$200,8,),IF(O29="blanco",VLOOKUP(N29,'Base perfiles'!$A$3:$O$200,7),IF(O29="ANODIZADO",VLOOKUP(N29,'Base perfiles'!$A$3:$O$200,6))))) | T29: =IF(S29="","",P29*Q29/VLOOKUP(N29,'Base perfiles'!$A$3:$O$200,3,)*S29*(1-R29)*1.105)
F30: 0.1 | G30: =IF(B30="","",IF(C30="negro",VLOOKUP(B30,'Base perfiles'!$A$3:$O$200,8,),IF(C30="blanco",VLOOKUP(B30,'Base perfiles'!$A$3:$O$200,7),IF(C30="ANODIZADO",VLOOKUP(B30,'Base perfiles'!$A$3:$O$200,6))))) | H30: =IF(G30="","",D30*E30/VLOOKUP(B30,'Base perfiles'!$A$3:$O$200,3,)*G30*(1-F30)*1.105) | R30: 0.1 | S30: =IF(N30="","",IF(O30="negro",VLOOKUP(N30,'Base perfiles'!$A$3:$O$200,8,),IF(O30="blanco",VLOOKUP(N30,'Base perfiles'!$A$3:$O$200,7),IF(O30="ANODIZADO",VLOOKUP(N30,'Base perfiles'!$A$3:$O$200,6))))) | T30: =IF(S30="","",P30*Q30/VLOOKUP(N30,'Base perfiles'!$A$3:$O$200,3,)*S30*(1-R30)*1.105)
... F149: 0.1 | G149: =IF(B149="","",IF(C149="negro",VLOOKUP(B149,'Base perfiles'!$A$3:$O$200,8,),IF(C149="blanco",VLOOKUP(B149,'Base perfiles'!$A$3:$O$200,7),IF(C149="ANODIZADO",VLOOKUP(B149,'Base perfiles'!$A$3:$O$200,6))))) | H149: =IF(G149="","",D149*E149/VLOOKUP(B149,'Base perfiles'!$A$3:$O$200,3,)*G149*(1-F149)*1.105) | R149: 0.1 | S149: =IF(N149="","",IF(O149="negro",VLOOKUP(N149,'Base perfiles'!$A$3:$O$200,8,),IF(O149="blanco",VLOOKUP(N149,'Base perfiles'!$A$3:$O$200,7),IF(O149="ANODIZADO",VLOOKUP(N149,'Base perfiles'!$A$3:$O$200,6))))) | T149: =IF(S149="","",P149*Q149/VLOOKUP(N149,'Base perfiles'!$A$3:$O$200,3,)*S149*(1-R149)*1.105)
G150: =IF(B150="","",IF(C150="negro",VLOOKUP(B150,'Base perfiles'!$A$3:$O$200,8,),IF(C150="blanco",VLOOKUP(B150,'Base perfiles'!$A$3:$O$200,7),IF(C150="ANODIZADO",VLOOKUP(B150,'Base perfiles'!$A$3:$O$200,6))))) | H150: =IF(G150="","",D150*E150/VLOOKUP(B150,'Base perfiles'!$A$3:$O$200,3,)*G150*(1-F150)*1.105) | R150: 0.1 | S150: =IF(N150="","",IF(O150="negro",VLOOKUP(N150,'Base perfiles'!$A$3:$O$200,8,),IF(O150="blanco",VLOOKUP(N150,'Base perfiles'!$A$3:$O$200,7),IF(O150="ANODIZADO",VLOOKUP(N150,'Base perfiles'!$A$3:$O$200,6))))) | T150: =IF(S150="","",P150*Q150/VLOOKUP(N150,'Base perfiles'!$A$3:$O$200,3,)*S150*(1-R150)*1.105)
G151: =IF(B151="","",IF(C151="negro",VLOOKUP(B151,'Base perfiles'!$A$3:$O$200,8,),IF(C151="blanco",VLOOKUP(B151,'Base perfiles'!$A$3:$O$200,7),IF(C151="ANODIZADO",VLOOKUP(B151,'Base perfiles'!$A$3:$O$200,6))))) | H151: =IF(G151="","",D151*E151/VLOOKUP(B151,'Base perfiles'!$A$3:$O$200,3,)*G151*(1-F151)*1.105) | R151: 0.1 | S151: =IF(N151="","",IF(O151="negro",VLOOKUP(N151,'Base perfiles'!$A$3:$O$200,8,),IF(O151="blanco",VLOOKUP(N151,'Base perfiles'!$A$3:$O$200,7),IF(O151="ANODIZADO",VLOOKUP(N151,'Base perfiles'!$A$3:$O$200,6))))) | T151: =IF(S151="","",P151*Q151/VLOOKUP(N151,'Base perfiles'!$A$3:$O$200,3,)*S151*(1-R151)*1.105)
G152: =IF(B152="","",IF(C152="negro",VLOOKUP(B152,'Base perfiles'!$A$3:$O$200,8,),IF(C152="blanco",VLOOKUP(B152,'Base perfiles'!$A$3:$O$200,7),IF(C152="ANODIZADO",VLOOKUP(B152,'Base perfiles'!$A$3:$O$200,6))))) | H152: =IF(G152="","",D152*E152/VLOOKUP(B152,'Base perfiles'!$A$3:$O$200,3,)*G152*(1-F152)*1.105) | R152: 0.1 | S152: =IF(N152="","",IF(O152="negro",VLOOKUP(N152,'Base perfiles'!$A$3:$O$200,8,),IF(O152="blanco",VLOOKUP(N152,'Base perfiles'!$A$3:$O$200,7),IF(O152="ANODIZADO",VLOOKUP(N152,'Base perfiles'!$A$3:$O$200,6))))) | T152: =IF(S152="","",P152*Q152/VLOOKUP(N152,'Base perfiles'!$A$3:$O$200,3,)*S152*(1-R152)*1.105)
G153: =IF(B153="","",IF(C153="negro",VLOOKUP(B153,'Base perfiles'!$A$3:$O$200,8,),IF(C153="blanco",VLOOKUP(B153,'Base perfiles'!$A$3:$O$200,7),IF(C153="ANODIZADO",VLOOKUP(B153,'Base perfiles'!$A$3:$O$200,6))))) | H153: =IF(G153="","",D153*E153/VLOOKUP(B153,'Base perfiles'!$A$3:$O$200,3,)*G153*(1-F153)*1.105) | R153: 0.1 | S153: =IF(N153="","",IF(O153="negro",VLOOKUP(N153,'Base perfiles'!$A$3:$O$200,8,),IF(O153="blanco",VLOOKUP(N153,'Base perfiles'!$A$3:$O$200,7),IF(O153="ANODIZADO",VLOOKUP(N153,'Base perfiles'!$A$3:$O$200,6))))) | T153: =IF(S153="","",P153*Q153/VLOOKUP(N153,'Base perfiles'!$A$3:$O$200,3,)*S153*(1-R153)*1.105)
G154: =IF(B154="","",IF(C154="negro",VLOOKUP(B154,'Base perfiles'!$A$3:$O$200,8,),IF(C154="blanco",VLOOKUP(B154,'Base perfiles'!$A$3:$O$200,7),IF(C154="ANODIZADO",VLOOKUP(B154,'Base perfiles'!$A$3:$O$200,6))))) | H154: =IF(G154="","",D154*E154/VLOOKUP(B154,'Base perfiles'!$A$3:$O$200,3,)*G154*(1-F154)*1.105) | R154: 0.1 | S154: =IF(N154="","",IF(O154="negro",VLOOKUP(N154,'Base perfiles'!$A$3:$O$200,8,),IF(O154="blanco",VLOOKUP(N154,'Base perfiles'!$A$3:$O$200,7),IF(O154="ANODIZADO",VLOOKUP(N154,'Base perfiles'!$A$3:$O$200,6))))) | T154: =IF(S154="","",P154*Q154/VLOOKUP(N154,'Base perfiles'!$A$3:$O$200,3,)*S154*(1-R154)*1.105)
G155: =IF(B155="","",IF(C155="negro",VLOOKUP(B155,'Base perfiles'!$A$3:$O$200,8,),IF(C155="blanco",VLOOKUP(B155,'Base perfiles'!$A$3:$O$200,7),IF(C155="ANODIZADO",VLOOKUP(B155,'Base perfiles'!$A$3:$O$200,6))))) | H155: =IF(G155="","",D155*E155/VLOOKUP(B155,'Base perfiles'!$A$3:$O$200,3,)*G155*(1-F155)*1.105) | R155: 0.1 | S155: =IF(N155="","",IF(O155="negro",VLOOKUP(N155,'Base perfiles'!$A$3:$O$200,8,),IF(O155="blanco",VLOOKUP(N155,'Base perfiles'!$A$3:$O$200,7),IF(O155="ANODIZADO",VLOOKUP(N155,'Base perfiles'!$A$3:$O$200,6))))) | T155: =IF(S155="","",P155*Q155/VLOOKUP(N155,'Base perfiles'!$A$3:$O$200,3,)*S155*(1-R155)*1.105)
G156: =IF(B156="","",IF(C156="negro",VLOOKUP(B156,'Base perfiles'!$A$3:$O$200,8,),IF(C156="blanco",VLOOKUP(B156,'Base perfiles'!$A$3:$O$200,7),IF(C156="ANODIZADO",VLOOKUP(B156,'Base perfiles'!$A$3:$O$200,6))))) | H156: =IF(G156="","",D156*E156/VLOOKUP(B156,'Base perfiles'!$A$3:$O$200,3,)*G156*(1-F156)*1.105) | R156: 0.1 | S156: =IF(N156="","",IF(O156="negro",VLOOKUP(N156,'Base perfiles'!$A$3:$O$200,8,),IF(O156="blanco",VLOOKUP(N156,'Base perfiles'!$A$3:$O$200,7),IF(O156="ANODIZADO",VLOOKUP(N156,'Base perfiles'!$A$3:$O$200,6))))) | T156: =IF(S156="","",P156*Q156/VLOOKUP(N156,'Base perfiles'!$A$3:$O$200,3,)*S156*(1-R156)*1.105)
G157: =IF(B157="","",IF(C157="negro",VLOOKUP(B157,'Base perfiles'!$A$3:$O$200,8,),IF(C157="blanco",VLOOKUP(B157,'Base perfiles'!$A$3:$O$200,7),IF(C157="ANODIZADO",VLOOKUP(B157,'Base perfiles'!$A$3:$O$200,6))))) | H157: =IF(G157="","",D157*E157/VLOOKUP(B157,'Base perfiles'!$A$3:$O$200,3,)*G157*(1-F157)*1.105) | R157: 0.1 | S157: =IF(N157="","",IF(O157="negro",VLOOKUP(N157,'Base perfiles'!$A$3:$O$200,8,),IF(O157="blanco",VLOOKUP(N157,'Base perfiles'!$A$3:$O$200,7),IF(O157="ANODIZADO",VLOOKUP(N157,'Base perfiles'!$A$3:$O$200,6))))) | T157: =IF(S157="","",P157*Q157/VLOOKUP(N157,'Base perfiles'!$A$3:$O$200,3,)*S157*(1-R157)*1.105)
G158: =IF(B158="","",IF(C158="negro",VLOOKUP(B158,'Base perfiles'!$A$3:$O$200,8,),IF(C158="blanco",VLOOKUP(B158,'Base perfiles'!$A$3:$O$200,7),IF(C158="ANODIZADO",VLOOKUP(B158,'Base perfiles'!$A$3:$O$200,6))))) | H158: =IF(G158="","",D158*E158/VLOOKUP(B158,'Base perfiles'!$A$3:$O$200,3,)*G158*(1-F158)*1.105) | R158: 0.1 | S158: =IF(N158="","",IF(O158="negro",VLOOKUP(N158,'Base perfiles'!$A$3:$O$200,8,),IF(O158="blanco",VLOOKUP(N158,'Base perfiles'!$A$3:$O$200,7),IF(O158="ANODIZADO",VLOOKUP(N158,'Base perfiles'!$A$3:$O$200,6))))) | T158: =IF(S158="","",P158*Q158/VLOOKUP(N158,'Base perfiles'!$A$3:$O$200,3,)*S158*(1-R158)*1.105)
G159: =IF(B159="","",IF(C159="negro",VLOOKUP(B159,'Base perfiles'!$A$3:$O$200,8,),IF(C159="blanco",VLOOKUP(B159,'Base perfiles'!$A$3:$O$200,7),IF(C159="ANODIZADO",VLOOKUP(B159,'Base perfiles'!$A$3:$O$200,6))))) | H159: =IF(G159="","",D159*E159/VLOOKUP(B159,'Base perfiles'!$A$3:$O$200,3,)*G159*(1-F159)*1.105) | R159: 0.1 | S159: =IF(N159="","",IF(O159="negro",VLOOKUP(N159,'Base perfiles'!$A$3:$O$200,8,),IF(O159="blanco",VLOOKUP(N159,'Base perfiles'!$A$3:$O$200,7),IF(O159="ANODIZADO",VLOOKUP(N159,'Base perfiles'!$A$3:$O$200,6))))) | T159: =IF(S159="","",P159*Q159/VLOOKUP(N159,'Base perfiles'!$A$3:$O$200,3,)*S159*(1-R159)*1.105)
G160: =IF(B160="","",IF(C160="negro",VLOOKUP(B160,'Base perfiles'!$A$3:$O$200,8,),IF(C160="blanco",VLOOKUP(B160,'Base perfiles'!$A$3:$O$200,7),IF(C160="ANODIZADO",VLOOKUP(B160,'Base perfiles'!$A$3:$O$200,6))))) | H160: =IF(G160="","",D160*E160/VLOOKUP(B160,'Base perfiles'!$A$3:$O$200,3,)*G160*(1-F160)*1.105) | R160: 0.1 | S160: =IF(N160="","",IF(O160="negro",VLOOKUP(N160,'Base perfiles'!$A$3:$O$200,8,),IF(O160="blanco",VLOOKUP(N160,'Base perfiles'!$A$3:$O$200,7),IF(O160="ANODIZADO",VLOOKUP(N160,'Base perfiles'!$A$3:$O$200,6))))) | T160: =IF(S160="","",P160*Q160/VLOOKUP(N160,'Base perfiles'!$A$3:$O$200,3,)*S160*(1-R160)*1.105)
...

Sheet Plantilla Pedido
A1: CODIGO | B1: COLOR | C1: CANTIDAD | D1: BONIF. | E1: $/barra S/B | F1: TOTAL C 10,5 BONIF | G1: TOTAL S/IVA BONIF | H1: TOTAL C /IVA | K1: Total C/10,5% | L1: Total S/iva | M1: Total C/Iva
A2: 200 | B2: Negro | C2: 0 | D2: 0.1 | E2: =IF(A2="","",IF(B2="Blanco",VLOOKUP(A2,'Base perfiles'!$A$3:$O$200,7,FALSE()),IF(B2="negro",VLOOKUP(A2,'Base perfiles'!$A$3:$O$200,8,FALSE()),IF(B2="anodizado",VLOOKUP(A2,'Base perfiles'!$A$3:$O$200,6,FALSE()),"")))) | F2: =IF(E2="","",C2*E2*(1-D2)*1.105) | G2: =IF(F2="","",F2/1.105) | H2: =IF(G2="","",G2*1.21) | K2: =SUM(Tabla_2[TOTAL C 10,5 BONIF]) | L2: =SUM(Tabla_2[TOTAL S/IVA BONIF]) | M2: =SUM(Tabla_2[TOTAL C /IVA])
A3: 201 | B3: Negro | C3: 0 | D3: 0.1 | E3: =IF(A3="","",IF(B3="Blanco",VLOOKUP(A3,'Base perfiles'!$A$3:$O$200,7,FALSE()),IF(B3="negro",VLOOKUP(A3,'Base perfiles'!$A$3:$O$200,8,FALSE()),IF(B3="anodizado",VLOOKUP(A3,'Base perfiles'!$A$3:$O$200,6,FALSE()),"")))) | F3: =IF(E3="","",C3*E3*(1-D3)*1.105) | G3: =IF(F3="","",F3/1.105) | H3: =IF(G3="","",G3*1.21)
A4: 203 | B4: Negro | C4: 0 | D4: 0.1 | E4: =IF(A4="","",IF(B4="Blanco",VLOOKUP(A4,'Base perfiles'!$A$3:$O$200,7,FALSE()),IF(B4="negro",VLOOKUP(A4,'Base perfiles'!$A$3:$O$200,8,FALSE()),IF(B4="anodizado",VLOOKUP(A4,'Base perfiles'!$A$3:$O$200,6,FALSE()),"")))) | F4: =IF(E4="","",C4*E4*(1-D4)*1.105) | G4: =IF(F4="","",F4/1.105) | H4: =IF(G4="","",G4*1.21)
A5: 204 | B5: Negro | C5: 0 | D5: 0.1 | E5: =IF(A5="","",IF(B5="Blanco",VLOOKUP(A5,'Base perfiles'!$A$3:$O$200,7,FALSE()),IF(B5="negro",VLOOKUP(A5,'Base perfiles'!$A$3:$O$200,8,FALSE()),IF(B5="anodizado",VLOOKUP(A5,'Base perfiles'!$A$3:$O$200,6,FALSE()),"")))) | F5: =IF(E5="","",C5*E5*(1-D5)*1.105) | G5: =IF(F5="","",F5/1.105) | H5: =IF(G5="","",G5*1.21)
A6: 206 | B6: Negro | C6: 0 | D6: 0.1 | E6: =IF(A6="","",IF(B6="Blanco",VLOOKUP(A6,'Base perfiles'!$A$3:$O$200,7,FALSE()),IF(B6="negro",VLOOKUP(A6,'Base perfiles'!$A$3:$O$200,8,FALSE()),IF(B6="anodizado",VLOOKUP(A6,'Base perfiles'!$A$3:$O$200,6,FALSE()),"")))) | F6: =IF(E6="","",C6*E6*(1-D6)*1.105) | G6: =IF(F6="","",F6/1.105) | H6: =IF(G6="","",G6*1.21)
A7: 207 | B7: Negro | C7: 0 | D7: 0.1 | E7: =IF(A7="","",IF(B7="Blanco",VLOOKUP(A7,'Base perfiles'!$A$3:$O$200,7,FALSE()),IF(B7="negro",VLOOKUP(A7,'Base perfiles'!$A$3:$O$200,8,FALSE()),IF(B7="anodizado",VLOOKUP(A7,'Base perfiles'!$A$3:$O$200,6,FALSE()),"")))) | F7: =IF(E7="","",C7*E7*(1-D7)*1.105) | G7: =IF(F7="","",F7/1.105) | H7: =IF(G7="","",G7*1.21)
A8: 213 | B8: Negro | C8: 0 | D8: 0.1 | E8: =IF(A8="","",IF(B8="Blanco",VLOOKUP(A8,'Base perfiles'!$A$3:$O$200,7,FALSE()),IF(B8="negro",VLOOKUP(A8,'Base perfiles'!$A$3:$O$200,8,FALSE()),IF(B8="anodizado",VLOOKUP(A8,'Base perfiles'!$A$3:$O$200,6,FALSE()),"")))) | F8: =IF(E8="","",C8*E8*(1-D8)*1.105) | G8: =IF(F8="","",F8/1.105) | H8: =IF(G8="","",G8*1.21)
A9: 214 | B9: Negro | C9: 0 | D9: 0.1 | E9: =IF(A9="","",IF(B9="Blanco",VLOOKUP(A9,'Base perfiles'!$A$3:$O$200,7,FALSE()),IF(B9="negro",VLOOKUP(A9,'Base perfiles'!$A$3:$O$200,8,FALSE()),IF(B9="anodizado",VLOOKUP(A9,'Base perfiles'!$A$3:$O$200,6,FALSE()),"")))) | F9: =IF(E9="","",C9*E9*(1-D9)*1.105) | G9: =IF(F9="","",F9/1.105) | H9: =IF(G9="","",G9*1.21)
A10: 216 | B10: Negro | C10: 0 | D10: 0.1 | E10: =IF(A10="","",IF(B10="Blanco",VLOOKUP(A10,'Base perfiles'!$A$3:$O$200,7,FALSE()),IF(B10="negro",VLOOKUP(A10,'Base perfiles'!$A$3:$O$200,8,FALSE()),IF(B10="anodizado",VLOOKUP(A10,'Base perfiles'!$A$3:$O$200,6,FALSE()),"")))) | F10: =IF(E10="","",C10*E10*(1-D10)*1.105) | G10: =IF(F10="","",F10/1.105) | H10: =IF(G10="","",G10*1.21)
A11: 217 | B11: Negro | C11: 0 | D11: 0.1 | E11: =IF(A11="","",IF(B11="Blanco",VLOOKUP(A11,'Base perfiles'!$A$3:$O$200,7,FALSE()),IF(B11="negro",VLOOKUP(A11,'Base perfiles'!$A$3:$O$200,8,FALSE()),IF(B11="anodizado",VLOOKUP(A11,'Base perfiles'!$A$3:$O$200,6,FALSE()),"")))) | F11: =IF(E11="","",C11*E11*(1-D11)*1.105) | G11: =IF(F11="","",F11/1.105) | H11: =IF(G11="","",G11*1.21)
A12: 219 | B12: Negro | C12: 0 | D12: 0.1 | E12: =IF(A12="","",IF(B12="Blanco",VLOOKUP(A12,'Base perfiles'!$A$3:$O$200,7,FALSE()),IF(B12="negro",VLOOKUP(A12,'Base perfiles'!$A$3:$O$200,8,FALSE()),IF(B12="anodizado",VLOOKUP(A12,'Base perfiles'!$A$3:$O$200,6,FALSE()),"")))) | F12: =IF(E12="","",C12*E12*(1-D12)*1.105) | G12: =IF(F12="","",F12/1.105) | H12: =IF(G12="","",G12*1.21)
A13: 230 | B13: Negro | C13: 0 | D13: 0.1 | E13: =IF(A13="","",IF(B13="Blanco",VLOOKUP(A13,'Base perfiles'!$A$3:$O$200,7,FALSE()),IF(B13="negro",VLOOKUP(A13,'Base perfiles'!$A$3:$O$200,8,FALSE()),IF(B13="anodizado",VLOOKUP(A13,'Base perfiles'!$A$3:$O$200,6,FALSE()),"")))) | F13: =IF(E13="","",C13*E13*(1-D13)*1.105) | G13: =IF(F13="","",F13/1.105) | H13: =IF(G13="","",G13*1.21)
A14: 231 | B14: Negro | C14: 0 | D14: 0.1 | E14: =IF(A14="","",IF(B14="Blanco",VLOOKUP(A14,'Base perfiles'!$A$3:$O$200,7,FALSE()),IF(B14="negro",VLOOKUP(A14,'Base perfiles'!$A$3:$O$200,8,FALSE()),IF(B14="anodizado",VLOOKUP(A14,'Base perfiles'!$A$3:$O$200,6,FALSE()),"")))) | F14: =IF(E14="","",C14*E14*(1-D14)*1.105) | G14: =IF(F14="","",F14/1.105) | H14: =IF(G14="","",G14*1.21)
... A28: 6514 | B28: Negro | C28: 0 | D28: 0.1 | E28: =IF(A28="","",IF(B28="Blanco",VLOOKUP(A28,'Base perfiles'!$A$3:$O$200,7,FALSE()),IF(B28="negro",VLOOKUP(A28,'Base perfiles'!$A$3:$O$200,8,FALSE()),IF(B28="anodizado",VLOOKUP(A28,'Base perfiles'!$A$3:$O$200,6,FALSE()),"")))) | F28: =IF(E28="","",C28*E28*(1-D28)*1.105) | G28: =IF(F28="","",F28/1.105) | H28: =IF(G28="","",G28*1.21)
D29: 0.1 | E29: =IF(A29="","",IF(B29="Blanco",VLOOKUP(A29,'Base perfiles'!$A$3:$O$200,7,FALSE()),IF(B29="negro",VLOOKUP(A29,'Base perfiles'!$A$3:$O$200,8,FALSE()),IF(B29="anodizado",VLOOKUP(A29,'Base perfiles'!$A$3:$O$200,6,FALSE()),"")))) | F29: =IF(E29="","",C29*E29*(1-D29)*1.105) | G29: =IF(F29="","",F29/1.105) | H29: =IF(G29="","",G29*1.21)
D30: 0.1 | E30: =IF(A30="","",IF(B30="Blanco",VLOOKUP(A30,'Base perfiles'!$A$3:$O$200,7,FALSE()),IF(B30="negro",VLOOKUP(A30,'Base perfiles'!$A$3:$O$200,8,FALSE()),IF(B30="anodizado",VLOOKUP(A30,'Base perfiles'!$A$3:$O$200,6,FALSE()),"")))) | F30: =IF(E30="","",C30*E30*(1-D30)*1.105) | G30: =IF(F30="","",F30/1.105) | H30: =IF(G30="","",G30*1.21)
D31: 0.1 | E31: =IF(A31="","",IF(B31="Blanco",VLOOKUP(A31,'Base perfiles'!$A$3:$O$200,7,FALSE()),IF(B31="negro",VLOOKUP(A31,'Base perfiles'!$A$3:$O$200,8,FALSE()),IF(B31="anodizado",VLOOKUP(A31,'Base perfiles'!$A$3:$O$200,6,FALSE()),"")))) | F31: =IF(E31="","",C31*E31*(1-D31)*1.105) | G31: =IF(F31="","",F31/1.105) | H31: =IF(G31="","",G31*1.21)
D32: 0.1 | E32: =IF(A32="","",IF(B32="Blanco",VLOOKUP(A32,'Base perfiles'!$A$3:$O$200,7,FALSE()),IF(B32="negro",VLOOKUP(A32,'Base perfiles'!$A$3:$O$200,8,FALSE()),IF(B32="anodizado",VLOOKUP(A32,'Base perfiles'!$A$3:$O$200,6,FALSE()),"")))) | F32: =IF(E32="","",C32*E32*(1-D32)*1.105) | G32: =IF(F32="","",F32/1.105) | H32: =IF(G32="","",G32*1.21)
D33: 0.1 | E33: =IF(A33="","",IF(B33="Blanco",VLOOKUP(A33,'Base perfiles'!$A$3:$O$200,7,FALSE()),IF(B33="negro",VLOOKUP(A33,'Base perfiles'!$A$3:$O$200,8,FALSE()),IF(B33="anodizado",VLOOKUP(A33,'Base perfiles'!$A$3:$O$200,6,FALSE()),"")))) | F33: =IF(E33="","",C33*E33*(1-D33)*1.105) | G33: =IF(F33="","",F33/1.105) | H33: =IF(G33="","",G33*1.21)
D34: 0.1 | E34: =IF(A34="","",IF(B34="Blanco",VLOOKUP(A34,'Base perfiles'!$A$3:$O$200,7,FALSE()),IF(B34="negro",VLOOKUP(A34,'Base perfiles'!$A$3:$O$200,8,FALSE()),IF(B34="anodizado",VLOOKUP(A34,'Base perfiles'!$A$3:$O$200,6,FALSE()),"")))) | F34: =IF(E34="","",C34*E34*(1-D34)*1.105) | G34: =IF(F34="","",F34/1.105) | H34: =IF(G34="","",G34*1.21)
D35: 0.1 | E35: =IF(A35="","",IF(B35="Blanco",VLOOKUP(A35,'Base perfiles'!$A$3:$O$200,7,FALSE()),IF(B35="negro",VLOOKUP(A35,'Base perfiles'!$A$3:$O$200,8,FALSE()),IF(B35="anodizado",VLOOKUP(A35,'Base perfiles'!$A$3:$O$200,6,FALSE()),"")))) | F35: =IF(E35="","",C35*E35*(1-D35)*1.105) | G35: =IF(F35="","",F35/1.105) | H35: =IF(G35="","",G35*1.21)
D36: 0.1 | E36: =IF(A36="","",IF(B36="Blanco",VLOOKUP(A36,'Base perfiles'!$A$3:$O$200,7,FALSE()),IF(B36="negro",VLOOKUP(A36,'Base perfiles'!$A$3:$O$200,8,FALSE()),IF(B36="anodizado",VLOOKUP(A36,'Base perfiles'!$A$3:$O$200,6,FALSE()),"")))) | F36: =IF(E36="","",C36*E36*(1-D36)*1.105) | G36: =IF(F36="","",F36/1.105) | H36: =IF(G36="","",G36*1.21)
D37: 0.1 | E37: =IF(A37="","",IF(B37="Blanco",VLOOKUP(A37,'Base perfiles'!$A$3:$O$200,7,FALSE()),IF(B37="negro",VLOOKUP(A37,'Base perfiles'!$A$3:$O$200,8,FALSE()),IF(B37="anodizado",VLOOKUP(A37,'Base perfiles'!$A$3:$O$200,6,FALSE()),"")))) | F37: =IF(E37="","",C37*E37*(1-D37)*1.105) | G37: =IF(F37="","",F37/1.105) | H37: =IF(G37="","",G37*1.21)
D38: 0.1 | E38: =IF(A38="","",IF(B38="Blanco",VLOOKUP(A38,'Base perfiles'!$A$3:$O$200,7,FALSE()),IF(B38="negro",VLOOKUP(A38,'Base perfiles'!$A$3:$O$200,8,FALSE()),IF(B38="anodizado",VLOOKUP(A38,'Base perfiles'!$A$3:$O$200,6,FALSE()),"")))) | F38: =IF(E38="","",C38*E38*(1-D38)*1.105) | G38: =IF(F38="","",F38/1.105) | H38: =IF(G38="","",G38*1.21)
D39: 0.1 | E39: =IF(A39="","",IF(B39="Blanco",VLOOKUP(A39,'Base perfiles'!$A$3:$O$200,7,FALSE()),IF(B39="negro",VLOOKUP(A39,'Base perfiles'!$A$3:$O$200,8,FALSE()),IF(B39="anodizado",VLOOKUP(A39,'Base perfiles'!$A$3:$O$200,6,FALSE()),"")))) | F39: =IF(E39="","",C39*E39*(1-D39)*1.105) | G39: =IF(F39="","",F39/1.105) | H39: =IF(G39="","",G39*1.21)
D40: 0.1 | E40: =IF(A40="","",IF(B40="Blanco",VLOOKUP(A40,'Base perfiles'!$A$3:$O$200,7,FALSE()),IF(B40="negro",VLOOKUP(A40,'Base perfiles'!$A$3:$O$200,8,FALSE()),IF(B40="anodizado",VLOOKUP(A40,'Base perfiles'!$A$3:$O$200,6,FALSE()),"")))) | F40: =IF(E40="","",C40*E40*(1-D40)*1.105) | G40: =IF(F40="","",F40/1.105) | H40: =IF(G40="","",G40*1.21)
... D46: 0.1 | E46: =IF(A46="","",IF(B46="Blanco",VLOOKUP(A46,'Base perfiles'!$A$3:$O$200,7,FALSE()),IF(B46="negro",VLOOKUP(A46,'Base perfiles'!$A$3:$O$200,8,FALSE()),IF(B46="anodizado",VLOOKUP(A46,'Base perfiles'!$A$3:$O$200,6,FALSE()),"")))) | F46: =IF(E46="","",C46*E46*(1-D46)*1.105) | G46: =IF(F46="","",F46/1.105) | H46: =IF(G46="","",G46*1.21)

Sheet Plantilla DVH
A2: TIP. | B2: LADO1 VIDRIO | C2: LADO2 VIDRIO | D2: CANT. | E2: VIDRIO1 | F2: VIDRIO2 | G2: CAMARA | H2: VALVULA | I2: PER. (ML) | J2: SUP. (M2) | K2: $ VIDRIO1 | L2: $ VIDRIO2 | M2: $TOTAL CAMARA | N2: $TOTAL VA | O2: $TOTAL U | P2: $TOTAL | Q2: $V1SR | R2: $V2SR | S2: $TOTALSR | T2: DIF | V2: TOTAL | W2: =SUM(Calculadora_DVH[$TOTAL])
A3: V1 | B3: 1135 | C3: 1535 | D3: 1 | E3: LAMIN3+3 | F3: T4 | G3: 12 | H3: NO | I3: =IF(AND(B3<>0,C3<>0),B3/1000*2+C3/1000*2,"") | J3: =IF(OR(B3="",C3=""),"",IF((B3/1000*C3/1000)>0.4,B3/1000*C3/1000,0.4)) | K3: =IF(OR(B3="",C3=""),"",VLOOKUP(E3,'Base vidrios'!$B$4:$C$16,2,FALSE())*J3) | L3: =IF(OR(C3="",B3=""),"",VLOOKUP(F3,'Base vidrios'!$B$4:$C$14,2,FALSE())*J3) | M3: =IF(I3="","",VLOOKUP(G3,'Base vidrios'!$E$4:$F$9,2,FALSE())*I3) | N3: =IF(M3="","",VLOOKUP(H3,'Base vidrios'!$H$4:$I$5,2,FALSE())) | O3: =IF(M3="","",SUM(K3:N3)) | P3: =IF(O3="","",O3*D3) | Q3: =IF(OR($P3="",$J3>0.4),"",VLOOKUP(E3,'Base vidrios'!$B$4:$C$13,2,FALSE())*$B3/1000*$C3/1000) | R3: =IF(OR($P3="",$J3>0.4),"",VLOOKUP(F3,'Base vidrios'!$B$4:$C$11,2,FALSE())*$B3/1000*$C3/1000) | S3: =IF(R3="","",R3+Q3+M3) | T3: =IF(S3="","",P3-S3*D3) | V3: RECARGO | W3: =SUM(Calculadora_DVH[DIF])
A4: V2 | B4: 1633 | C4: 1535 | D4: 1 | E4: LAMIN3+3 | F4: T4 | G4: 12 | H4: NO | I4: =IF(AND(B4<>0,C4<>0),B4/1000*2+C4/1000*2,"") | J4: =IF(OR(B4="",C4=""),"",IF((B4/1000*C4/1000)>0.4,B4/1000*C4/1000,0.4)) | K4: =IF(OR(B4="",C4=""),"",VLOOKUP(E4,'Base vidrios'!$B$4:$C$16,2,FALSE())*J4) | L4: =IF(OR(C4="",B4=""),"",VLOOKUP(F4,'Base vidrios'!$B$4:$C$14,2,FALSE())*J4) | M4: =IF(I4="","",VLOOKUP(G4,'Base vidrios'!$E$4:$F$9,2,FALSE())*I4) | N4: =IF(M4="","",VLOOKUP(H4,'Base vidrios'!$H$4:$I$5,2,FALSE())) | O4: =IF(M4="","",SUM(K4:N4)) | P4: =IF(O4="","",O4*D4) | Q4: =IF(OR($P4="",$J4>0.4),"",VLOOKUP(E4,'Base vidrios'!$B$4:$C$13,2,FALSE())*$B4/1000*$C4/1000) | R4: =IF(OR($P4="",$J4>0.4),"",VLOOKUP(F4,'Base vidrios'!$B$4:$C$11,2,FALSE())*$B4/1000*$C4/1000) | S4: =IF(R4="","",R4+Q4+M4) | T4: =IF(S4="","",P4-S4*D4)
A5: V2 | B5: 364 | C5: 1466 | D5: 1 | E5: LAMIN3+3 | F5: T4 | G5: 12 | H5: NO | I5: =IF(AND(B5<>0,C5<>0),B5/1000*2+C5/1000*2,"") | J5: =IF(OR(B5="",C5=""),"",IF((B5/1000*C5/1000)>0.4,B5/1000*C5/1000,0.4)) | K5: =IF(OR(B5="",C5=""),"",VLOOKUP(E5,'Base vidrios'!$B$4:$C$16,2,FALSE())*J5) | L5: =IF(OR(C5="",B5=""),"",VLOOKUP(F5,'Base vidrios'!$B$4:$C$14,2,FALSE())*J5) | M5: =IF(I5="","",VLOOKUP(G5,'Base vidrios'!$E$4:$F$9,2,FALSE())*I5) | N5: =IF(M5="","",VLOOKUP(H5,'Base vidrios'!$H$4:$I$5,2,FALSE())) | O5: =IF(M5="","",SUM(K5:N5)) | P5: =IF(O5="","",O5*D5) | Q5: =IF(OR($P5="",$J5>0.4),"",VLOOKUP(E5,'Base vidrios'!$B$4:$C$13,2,FALSE())*$B5/1000*$C5/1000) | R5: =IF(OR($P5="",$J5>0.4),"",VLOOKUP(F5,'Base vidrios'!$B$4:$C$11,2,FALSE())*$B5/1000*$C5/1000) | S5: =IF(R5="","",R5+Q5+M5) | T5: =IF(S5="","",P5-S5*D5) | V5: Precio 1
A6: V3 | B6: 403 | C6: 1331 | D6: 2 | E6: LAMIN3+3 | F6: T4 | G6: 9 | H6: NO | I6: =IF(AND(B6<>0,C6<>0),B6/1000*2+C6/1000*2,"") | J6: =IF(OR(B6="",C6=""),"",IF((B6/1000*C6/1000)>0.4,B6/1000*C6/1000,0.4)) | K6: =IF(OR(B6="",C6=""),"",VLOOKUP(E6,'Base vidrios'!$B$4:$C$16,2,FALSE())*J6) | L6: =IF(OR(C6="",B6=""),"",VLOOKUP(F6,'Base vidrios'!$B$4:$C$14,2,FALSE())*J6) | M6: =IF(I6="","",VLOOKUP(G6,'Base vidrios'!$E$4:$F$9,2,FALSE())*I6) | N6: =IF(M6="","",VLOOKUP(H6,'Base vidrios'!$H$4:$I$5,2,FALSE())) | O6: =IF(M6="","",SUM(K6:N6)) | P6: =IF(O6="","",O6*D6) | Q6: =IF(OR($P6="",$J6>0.4),"",VLOOKUP(E6,'Base vidrios'!$B$4:$C$13,2,FALSE())*$B6/1000*$C6/1000) | R6: =IF(OR($P6="",$J6>0.4),"",VLOOKUP(F6,'Base vidrios'!$B$4:$C$11,2,FALSE())*$B6/1000*$C6/1000) | S6: =IF(R6="","",R6+Q6+M6) | T6: =IF(S6="","",P6-S6*D6) | V6: Precio 3+3 | W6: =W2
A7: V5 | B7: 408 | C7: 1401 | D7: 2 | E7: LAMIN3+3 | F7: T4 | G7: 9 | H7: NO | I7: =IF(AND(B7<>0,C7<>0),B7/1000*2+C7/1000*2,"") | J7: =IF(OR(B7="",C7=""),"",IF((B7/1000*C7/1000)>0.4,B7/1000*C7/1000,0.4)) | K7: =IF(OR(B7="",C7=""),"",VLOOKUP(E7,'Base vidrios'!$B$4:$C$16,2,FALSE())*J7) | L7: =IF(OR(C7="",B7=""),"",VLOOKUP(F7,'Base vidrios'!$B$4:$C$14,2,FALSE())*J7) | M7: =IF(I7="","",VLOOKUP(G7,'Base vidrios'!$E$4:$F$9,2,FALSE())*I7) | N7: =IF(M7="","",VLOOKUP(H7,'Base vidrios'!$H$4:$I$5,2,FALSE())) | O7: =IF(M7="","",SUM(K7:N7)) | P7: =IF(O7="","",O7*D7) | Q7: =IF(OR($P7="",$J7>0.4),"",VLOOKUP(E7,'Base vidrios'!$B$4:$C$13,2,FALSE())*$B7/1000*$C7/1000) | R7: =IF(OR($P7="",$J7>0.4),"",VLOOKUP(F7,'Base vidrios'!$B$4:$C$11,2,FALSE())*$B7/1000*$C7/1000) | S7: =IF(R7="","",R7+Q7+M7) | T7: =IF(S7="","",P7-S7*D7) | V7: Diferencia | W7: =W6-W5
A8: V6 | B8: 598 | C8: 1401 | D8: 2 | E8: LAMIN3+3 | F8: T4 | G8: 9 | H8: NO | I8: =IF(AND(B8<>0,C8<>0),B8/1000*2+C8/1000*2,"") | J8: =IF(OR(B8="",C8=""),"",IF((B8/1000*C8/1000)>0.4,B8/1000*C8/1000,0.4)) | K8: =IF(OR(B8="",C8=""),"",VLOOKUP(E8,'Base vidrios'!$B$4:$C$16,2,FALSE())*J8) | L8: =IF(OR(C8="",B8=""),"",VLOOKUP(F8,'Base vidrios'!$B$4:$C$14,2,FALSE())*J8) | M8: =IF(I8="","",VLOOKUP(G8,'Base vidrios'!$E$4:$F$9,2,FALSE())*I8) | N8: =IF(M8="","",VLOOKUP(H8,'Base vidrios'!$H$4:$I$5,2,FALSE())) | O8: =IF(M8="","",SUM(K8:N8)) | P8: =IF(O8="","",O8*D8) | Q8: =IF(OR($P8="",$J8>0.4),"",VLOOKUP(E8,'Base vidrios'!$B$4:$C$13,2,FALSE())*$B8/1000*$C8/1000) | R8: =IF(OR($P8="",$J8>0.4),"",VLOOKUP(F8,'Base vidrios'!$B$4:$C$11,2,FALSE())*$B8/1000*$C8/1000) | S8: =IF(R8="","",R8+Q8+M8) | T8: =IF(S8="","",P8-S8*D8) | V8: Diferencia c/utilidad | W8: =W7*1.5
H9: NO | I9: =IF(AND(B9<>0,C9<>0),B9/1000*2+C9/1000*2,"") | J9: =IF(OR(B9="",C9=""),"",IF((B9/1000*C9/1000)>0.4,B9/1000*C9/1000,0.4)) | K9: =IF(OR(B9="",C9=""),"",VLOOKUP(E9,'Base vidrios'!$B$4:$C$16,2,FALSE())*J9) | L9: =IF(OR(C9="",B9=""),"",VLOOKUP(F9,'Base vidrios'!$B$4:$C$14,2,FALSE())*J9) | M9: =IF(I9="","",VLOOKUP(G9,'Base vidrios'!$E$4:$F$9,2,FALSE())*I9) | N9: =IF(M9="","",VLOOKUP(H9,'Base vidrios'!$H$4:$I$5,2,FALSE())) | O9: =IF(M9="","",SUM(K9:N9)) | P9: =IF(O9="","",O9*D9) | Q9: =IF(OR($P9="",$J9>0.4),"",VLOOKUP(E9,'Base vidrios'!$B$4:$C$13,2,FALSE())*$B9/1000*$C9/1000) | R9: =IF(OR($P9="",$J9>0.4),"",VLOOKUP(F9,'Base vidrios'!$B$4:$C$11,2,FALSE())*$B9/1000*$C9/1000) | S9: =IF(R9="","",R9+Q9+M9) | T9: =IF(S9="","",P9-S9*D9)
H10: NO | I10: =IF(AND(B10<>0,C10<>0),B10/1000*2+C10/1000*2,"") | J10: =IF(OR(B10="",C10=""),"",IF((B10/1000*C10/1000)>0.4,B10/1000*C10/1000,0.4)) | K10: =IF(OR(B10="",C10=""),"",VLOOKUP(E10,'Base vidrios'!$B$4:$C$16,2,FALSE())*J10) | L10: =IF(OR(C10="",B10=""),"",VLOOKUP(F10,'Base vidrios'!$B$4:$C$14,2,FALSE())*J10) | M10: =IF(I10="","",VLOOKUP(G10,'Base vidrios'!$E$4:$F$9,2,FALSE())*I10) | N10: =IF(M10="","",VLOOKUP(H10,'Base vidrios'!$H$4:$I$5,2,FALSE())) | O10: =IF(M10="","",SUM(K10:N10)) | P10: =IF(O10="","",O10*D10) | Q10: =IF(OR($P10="",$J10>0.4),"",VLOOKUP(E10,'Base vidrios'!$B$4:$C$13,2,FALSE())*$B10/1000*$C10/1000) | R10: =IF(OR($P10="",$J10>0.4),"",VLOOKUP(F10,'Base vidrios'!$B$4:$C$11,2,FALSE())*$B10/1000*$C10/1000) | S10: =IF(R10="","",R10+Q10+M10) | T10: =IF(S10="","",P10-S10*D10)
H11: NO | I11: =IF(AND(B11<>0,C11<>0),B11/1000*2+C11/1000*2,"") | J11: =IF(OR(B11="",C11=""),"",IF((B11/1000*C11/1000)>0.4,B11/1000*C11/1000,0.4)) | K11: =IF(OR(B11="",C11=""),"",VLOOKUP(E11,'Base vidrios'!$B$4:$C$16,2,FALSE())*J11) | L11: =IF(OR(C11="",B11=""),"",VLOOKUP(F11,'Base vidrios'!$B$4:$C$14,2,FALSE())*J11) | M11: =IF(I11="","",VLOOKUP(G11,'Base vidrios'!$E$4:$F$9,2,FALSE())*I11) | N11: =IF(M11="","",VLOOKUP(H11,'Base vidrios'!$H$4:$I$5,2,FALSE())) | O11: =IF(M11="","",SUM(K11:N11)) | P11: =IF(O11="","",O11*D11) | Q11: =IF(OR($P11="",$J11>0.4),"",VLOOKUP(E11,'Base vidrios'!$B$4:$C$13,2,FALSE())*$B11/1000*$C11/1000) | R11: =IF(OR($P11="",$J11>0.4),"",VLOOKUP(F11,'Base vidrios'!$B$4:$C$11,2,FALSE())*$B11/1000*$C11/1000) | S11: =IF(R11="","",R11+Q11+M11) | T11: =IF(S11="","",P11-S11*D11)
H12: NO | I12: =IF(AND(B12<>0,C12<>0),B12/1000*2+C12/1000*2,"") | J12: =IF(OR(B12="",C12=""),"",IF((B12/1000*C12/1000)>0.4,B12/1000*C12/1000,0.4)) | K12: =IF(OR(B12="",C12=""),"",VLOOKUP(E12,'Base vidrios'!$B$4:$C$16,2,FALSE())*J12) | L12: =IF(OR(C12="",B12=""),"",VLOOKUP(F12,'Base vidrios'!$B$4:$C$14,2,FALSE())*J12) | M12: =IF(I12="","",VLOOKUP(G12,'Base vidrios'!$E$4:$F$9,2,FALSE())*I12) | N12: =IF(M12="","",VLOOKUP(H12,'Base vidrios'!$H$4:$I$5,2,FALSE())) | O12: =IF(M12="","",SUM(K12:N12)) | P12: =IF(O12="","",O12*D12) | Q12: =IF(OR($P12="",$J12>0.4),"",VLOOKUP(E12,'Base vidrios'!$B$4:$C$13,2,FALSE())*$B12/1000*$C12/1000) | R12: =IF(OR($P12="",$J12>0.4),"",VLOOKUP(F12,'Base vidrios'!$B$4:$C$11,2,FALSE())*$B12/1000*$C12/1000) | S12: =IF(R12="","",R12+Q12+M12) | T12: =IF(S12="","",P12-S12*D12)
H13: NO | I13: =IF(AND(B13<>0,C13<>0),B13/1000*2+C13/1000*2,"") | J13: =IF(OR(B13="",C13=""),"",IF((B13/1000*C13/1000)>0.4,B13/1000*C13/1000,0.4)) | K13: =IF(OR(B13="",C13=""),"",VLOOKUP(E13,'Base vidrios'!$B$4:$C$16,2,FALSE())*J13) | L13: =IF(OR(C13="",B13=""),"",VLOOKUP(F13,'Base vidrios'!$B$4:$C$14,2,FALSE())*J13) | M13: =IF(I13="","",VLOOKUP(G13,'Base vidrios'!$E$4:$F$9,2,FALSE())*I13) | N13: =IF(M13="","",VLOOKUP(H13,'Base vidrios'!$H$4:$I$5,2,FALSE())) | O13: =IF(M13="","",SUM(K13:N13)) | P13: =IF(O13="","",O13*D13) | Q13: =IF(OR($P13="",$J13>0.4),"",VLOOKUP(E13,'Base vidrios'!$B$4:$C$13,2,FALSE())*$B13/1000*$C13/1000) | R13: =IF(OR($P13="",$J13>0.4),"",VLOOKUP(F13,'Base vidrios'!$B$4:$C$11,2,FALSE())*$B13/1000*$C13/1000) | S13: =IF(R13="","",R13+Q13+M13) | T13: =IF(S13="","",P13-S13*D13)
H14: NO | I14: =IF(AND(B14<>0,C14<>0),B14/1000*2+C14/1000*2,"") | J14: =IF(OR(B14="",C14=""),"",IF((B14/1000*C14/1000)>0.4,B14/1000*C14/1000,0.4)) | K14: =IF(OR(B14="",C14=""),"",VLOOKUP(E14,'Base vidrios'!$B$4:$C$16,2,FALSE())*J14) | L14: =IF(OR(C14="",B14=""),"",VLOOKUP(F14,'Base vidrios'!$B$4:$C$14,2,FALSE())*J14) | M14: =IF(I14="","",VLOOKUP(G14,'Base vidrios'!$E$4:$F$9,2,FALSE())*I14) | N14: =IF(M14="","",VLOOKUP(H14,'Base vidrios'!$H$4:$I$5,2,FALSE())) | O14: =IF(M14="","",SUM(K14:N14)) | P14: =IF(O14="","",O14*D14) | Q14: =IF(OR($P14="",$J14>0.4),"",VLOOKUP(E14,'Base vidrios'!$B$4:$C$13,2,FALSE())*$B14/1000*$C14/1000) | R14: =IF(OR($P14="",$J14>0.4),"",VLOOKUP(F14,'Base vidrios'!$B$4:$C$11,2,FALSE())*$B14/1000*$C14/1000) | S14: =IF(R14="","",R14+Q14+M14) | T14: =IF(S14="","",P14-S14*D14)
